<?xml version="1.0" encoding="utf-8"?>
<!-- This URDF was automatically created by SolidWorks to URDF Exporter! Originally created by Stephen Brawner (brawner@gmail.com) 
     Commit Version: 1.6.0-1-g15f4949  Build Version: 1.6.7594.29634
     For more information, please see http://wiki.ros.org/sw_urdf_exporter -->
<robot
  name="simple_hand">
  <link
    name="base_link">
    <visual>
      <origin
        xyz="0 0 0"
        rpy="0 0 0" />
      <geometry>
        <mesh
          filename="package://simple_hand/meshes/base_link.STL" />
      </geometry>
      <material
        name="">
        <color
          rgba="0.792156862745098 0.819607843137255 0.933333333333333 1" />
      </material>
    </visual>
    <collision>
      <origin
        xyz="0 0 0"
        rpy="0 0 0" />
      <geometry>
        <mesh
          filename="package://simple_hand/meshes/base_link.STL" />
      </geometry>
    </collision>
  </link>
  <link
    name="thumb_1">
    <inertial>
      <origin
        xyz="0.0048085282615066 0.0155683292090754 -9.38862231650911E-05"
        rpy="0 0 0" />
      <mass
        value="0.00714658380829061" />
      <inertia
        ixx="3.26626039983406E-07"
        ixy="9.21851511766135E-08"
        ixz="7.28401970577157E-11"
        iyy="4.93450737768554E-07"
        iyz="1.16674127798342E-10"
        izz="6.67805464749945E-07" />
    </inertial>
    <visual>
      <origin
        xyz="0 0 0"
        rpy="0 0 0" />
      <geometry>
        <mesh
          filename="package://simple_hand/meshes/thumb_1.STL" />
      </geometry>
      <material
        name="">
        <color
          rgba="0.792156862745098 0.819607843137255 0.933333333333333 1" />
      </material>
    </visual>
    <collision>
      <origin
        xyz="0 0 0"
        rpy="0 0 0" />
      <geometry>
        <mesh
          filename="package://simple_hand/meshes/thumb_1.STL" />
      </geometry>
    </collision>
  </link>
  <joint
    name="thumb_palm"
    type="continuous">
    <origin
      xyz="-0.031 -0.0001 0"
      rpy="1.3963 1.5708 0" />
    <parent
      link="base_link" />
    <child
      link="thumb_1" />
    <axis
      xyz="1 0 0" />
  </joint>
  <link
    name="thumb_2">
    <inertial>
      <origin
        xyz="-0.0580525842144156 0.0245170365772038 0.006002121572846"
        rpy="0 0 0" />
      <mass
        value="0.00309410697808252" />
      <inertia
        ixx="9.86716393307871E-08"
        ixy="-6.5838141715037E-09"
        ixz="4.76941858010047E-11"
        iyy="8.17761446626134E-08"
        iyz="1.44734613015409E-11"
        izz="1.17680540570393E-07" />
    </inertial>
    <visual>
      <origin
        xyz="0 0 0"
        rpy="0 0 0" />
      <geometry>
        <mesh
          filename="package://simple_hand/meshes/thumb_2.STL" />
      </geometry>
      <material
        name="">
        <color
          rgba="0.792156862745098 0.819607843137255 0.933333333333333 1" />
      </material>
    </visual>
    <collision>
      <origin
        xyz="0 0 0"
        rpy="0 0 0" />
      <geometry>
        <mesh
          filename="package://simple_hand/meshes/thumb_2.STL" />
      </geometry>
    </collision>
  </link>
  <joint
    name="thumb_12"
    type="continuous">
    <origin
      xyz="0.00074168 -0.025588 -0.0138"
      rpy="-2.8356 0.43178 -1.5075" />
    <parent
      link="thumb_1" />
    <child
      link="thumb_2" />
    <axis
      xyz="1 0 0" />
  </joint>
  <link
    name="thumb_3">
    <inertial>
      <origin
        xyz="-0.0683569874934216 0.0647531465127789 0.00599440013402127"
        rpy="0 0 0" />
      <mass
        value="0.00324861748801508" />
      <inertia
        ixx="1.31829885963988E-07"
        ixy="2.37227938008643E-08"
        ixz="1.16060719333074E-12"
        iyy="8.56030195353301E-08"
        iyz="9.31995554585114E-13"
        izz="1.54481533062546E-07" />
    </inertial>
    <visual>
      <origin
        xyz="0 0 0"
        rpy="0 0 0" />
      <geometry>
        <mesh
          filename="package://simple_hand/meshes/thumb_3.STL" />
      </geometry>
      <material
        name="">
        <color
          rgba="0.792156862745098 0.819607843137255 0.933333333333333 1" />
      </material>
    </visual>
    <collision>
      <origin
        xyz="0 0 0"
        rpy="0 0 0" />
      <geometry>
        <mesh
          filename="package://simple_hand/meshes/thumb_3.STL" />
      </geometry>
    </collision>
  </link>
  <joint
    name="thumb_23"
    type="continuous">
    <origin
      xyz="0.010488 -0.0027249 0.0098784"
      rpy="0.031976 -0.17161 0.12773" />
    <parent
      link="thumb_2" />
    <child
      link="thumb_3" />
    <axis
      xyz="1 0 0" />
  </joint>
  <link
    name="index_1">
    <inertial>
      <origin
        xyz="0.000100909995287481 0.0101314105773068 -0.00308812397054953"
        rpy="0 0 0" />
      <mass
        value="0.00331457639559618" />
      <inertia
        ixx="1.2323138903352E-07"
        ixy="-6.25998515372946E-22"
        ixz="5.10066448911204E-22"
        iyy="8.32166997991831E-08"
        iyz="-2.40399550653692E-20"
        izz="1.40564829901929E-07" />
    </inertial>
    <visual>
      <origin
        xyz="0 0 0"
        rpy="0 0 0" />
      <geometry>
        <mesh
          filename="package://simple_hand/meshes/index_1.STL" />
      </geometry>
      <material
        name="">
        <color
          rgba="0.792156862745098 0.819607843137255 0.933333333333333 1" />
      </material>
    </visual>
    <collision>
      <origin
        xyz="0 0 0"
        rpy="0 0 0" />
      <geometry>
        <mesh
          filename="package://simple_hand/meshes/index_1.STL" />
      </geometry>
    </collision>
  </link>
  <joint
    name="index_palm"
    type="continuous">
    <origin
      xyz="-0.0299 0.0029 0.043"
      rpy="1.5708 0 3.1416" />
    <parent
      link="base_link" />
    <child
      link="index_1" />
    <axis
      xyz="-1 0 0" />
  </joint>
  <link
    name="index_2">
    <inertial>
      <origin
        xyz="8.81239705526511E-05 0.0101314105773068 -0.00291187602944456"
        rpy="0 0 0" />
      <mass
        value="0.00331457639559618" />
      <inertia
        ixx="1.2323138903352E-07"
        ixy="-6.31587710794479E-22"
        ixz="5.08654247771648E-22"
        iyy="8.32166997991831E-08"
        iyz="-2.39865496563743E-20"
        izz="1.40564829901929E-07" />
    </inertial>
    <visual>
      <origin
        xyz="0 0 0"
        rpy="0 0 0" />
      <geometry>
        <mesh
          filename="package://simple_hand/meshes/index_2.STL" />
      </geometry>
      <material
        name="">
        <color
          rgba="0.792156862745098 0.819607843137255 0.933333333333333 1" />
      </material>
    </visual>
    <collision>
      <origin
        xyz="0 0 0"
        rpy="0 0 0" />
      <geometry>
        <mesh
          filename="package://simple_hand/meshes/index_2.STL" />
      </geometry>
    </collision>
  </link>
  <joint
    name="index_12"
    type="continuous">
    <origin
      xyz="0.0002 0.03 0"
      rpy="0 0 0" />
    <parent
      link="index_1" />
    <child
      link="index_2" />
    <axis
      xyz="1 0 0" />
  </joint>
  <link
    name="index_3">
    <inertial>
      <origin
        xyz="-9.48443246826143E-05 0.0116226051015444 -0.00309484432468261"
        rpy="0 0 0" />
      <mass
        value="0.00352502395351663" />
      <inertia
        ixx="1.85717997302154E-07"
        ixy="-3.18200470047261E-23"
        ixz="-5.94013478540175E-24"
        iyy="8.01006878176001E-08"
        iyz="-5.7268420109026E-23"
        izz="1.97300854531169E-07" />
    </inertial>
    <visual>
      <origin
        xyz="0 0 0"
        rpy="0 0 0" />
      <geometry>
        <mesh
          filename="package://simple_hand/meshes/index_3.STL" />
      </geometry>
      <material
        name="">
        <color
          rgba="0.792156862745098 0.819607843137255 0.933333333333333 1" />
      </material>
    </visual>
    <collision>
      <origin
        xyz="0 0 0"
        rpy="0 0 0" />
      <geometry>
        <mesh
          filename="package://simple_hand/meshes/index_3.STL" />
      </geometry>
    </collision>
  </link>
  <joint
    name="index_23"
    type="fixed">
    <origin
      xyz="0 0.03 0"
      rpy="0 0 0" />
    <parent
      link="index_2" />
    <child
      link="index_3" />
    <axis
      xyz="0 0 0" />
  </joint>
  <link
    name="middle_1">
    <inertial>
      <origin
        xyz="-0.0075009099952875 0.0146314105773069 8.8123970549539E-05"
        rpy="0 0 0" />
      <mass
        value="0.00331457639559618" />
      <inertia
        ixx="1.2323138903352E-07"
        ixy="6.27050527505397E-22"
        ixz="5.23464626399803E-22"
        iyy="8.32166997991831E-08"
        iyz="2.39628438573508E-20"
        izz="1.40564829901929E-07" />
    </inertial>
    <visual>
      <origin
        xyz="0 0 0"
        rpy="0 0 0" />
      <geometry>
        <mesh
          filename="package://simple_hand/meshes/middle_1.STL" />
      </geometry>
      <material
        name="">
        <color
          rgba="0.792156862745098 0.819607843137255 0.933333333333333 1" />
      </material>
    </visual>
    <collision>
      <origin
        xyz="0 0 0"
        rpy="0 0 0" />
      <geometry>
        <mesh
          filename="package://simple_hand/meshes/middle_1.STL" />
      </geometry>
    </collision>
  </link>
  <joint
    name="middle_palm"
    type="continuous">
    <origin
      xyz="-0.003 0.0001 0.0435"
      rpy="-3.1416 0 0" />
    <parent
      link="base_link" />
    <child
      link="middle_1" />
    <axis
      xyz="1 0 0" />
  </joint>
  <link
    name="middle_2">
    <inertial>
      <origin
        xyz="0.000100909995287488 0.0101314105773067 -0.00291187602944463"
        rpy="0 0 0" />
      <mass
        value="0.00331457639559618" />
      <inertia
        ixx="1.2323138903352E-07"
        ixy="-6.67723660396906E-22"
        ixz="5.12480192862445E-22"
        iyy="8.32166997991831E-08"
        iyz="-2.35948874118925E-20"
        izz="1.40564829901929E-07" />
    </inertial>
    <visual>
      <origin
        xyz="0 0 0"
        rpy="0 0 0" />
      <geometry>
        <mesh
          filename="package://simple_hand/meshes/middle_2.STL" />
      </geometry>
      <material
        name="">
        <color
          rgba="0.792156862745098 0.819607843137255 0.933333333333333 1" />
      </material>
    </visual>
    <collision>
      <origin
        xyz="0 0 0"
        rpy="0 0 0" />
      <geometry>
        <mesh
          filename="package://simple_hand/meshes/middle_2.STL" />
      </geometry>
    </collision>
  </link>
  <joint
    name="middle_12"
    type="continuous">
    <origin
      xyz="-0.0076 0.033 0.0045"
      rpy="1.5708 0 3.1416" />
    <parent
      link="middle_1" />
    <child
      link="middle_2" />
    <axis
      xyz="1 0 0" />
  </joint>
  <link
    name="middle_3">
    <inertial>
      <origin
        xyz="-9.48443246826126E-05 0.0116226051015443 -0.00290515567531748"
        rpy="0 0 0" />
      <mass
        value="0.00352502395351663" />
      <inertia
        ixx="1.85717997302153E-07"
        ixy="1.03160885509049E-22"
        ixz="-1.87278463224465E-23"
        iyy="8.01006878176002E-08"
        iyz="9.5434799558797E-22"
        izz="1.97300854531168E-07" />
    </inertial>
    <visual>
      <origin
        xyz="0 0 0"
        rpy="0 0 0" />
      <geometry>
        <mesh
          filename="package://simple_hand/meshes/middle_3.STL" />
      </geometry>
      <material
        name="">
        <color
          rgba="0.792156862745098 0.819607843137255 0.933333333333333 1" />
      </material>
    </visual>
    <collision>
      <origin
        xyz="0 0 0"
        rpy="0 0 0" />
      <geometry>
        <mesh
          filename="package://simple_hand/meshes/middle_3.STL" />
      </geometry>
    </collision>
  </link>
  <joint
    name="middle_23"
    type="fixed">
    <origin
      xyz="0.0002 0.03 0"
      rpy="0 0 0" />
    <parent
      link="middle_2" />
    <child
      link="middle_3" />
    <axis
      xyz="0 0 0" />
  </joint>
  <link
    name="ring_pink_palm">
    <inertial>
      <origin
        xyz="0.017020767254047 0.00634175647982279 -8.33728651589595E-05"
        rpy="0 0 0" />
      <mass
        value="0.00474638182867953" />
      <inertia
        ixx="1.24617700851684E-07"
        ixy="8.08014945109771E-08"
        ixz="-3.25122701371497E-12"
        iyy="4.61877650491779E-07"
        iyz="1.81183357332401E-12"
        izz="4.81107731413793E-07" />
    </inertial>
    <visual>
      <origin
        xyz="0 0 0"
        rpy="0 0 0" />
      <geometry>
        <mesh
          filename="package://simple_hand/meshes/ring_pink_palm.STL" />
      </geometry>
      <material
        name="">
        <color
          rgba="0.792156862745098 0.819607843137255 0.933333333333333 1" />
      </material>
    </visual>
    <collision>
      <origin
        xyz="0 0 0"
        rpy="0 0 0" />
      <geometry>
        <mesh
          filename="package://simple_hand/meshes/ring_pink_palm.STL" />
      </geometry>
    </collision>
  </link>
  <joint
    name="rp_palm"
    type="continuous">
    <origin
      xyz="0.0032512 0.0001 0.018439"
      rpy="1.5708 0 0" />
    <parent
      link="base_link" />
    <child
      link="ring_pink_palm" />
    <axis
      xyz="0.98481 -0.17365 0" />
  </joint>
  <link
    name="ring_1">
    <inertial>
      <origin
        xyz="8.73292782338948E-05 -0.0107273450732419 0.0166617140891223"
        rpy="0 0 0" />
      <mass
        value="0.00334473888459067" />
      <inertia
        ixx="1.23940526073647E-07"
        ixy="2.91167575618666E-22"
        ixz="-6.82424005356248E-22"
        iyy="1.35896896376679E-07"
        iyz="1.58204423271736E-08"
        izz="8.93128789399372E-08" />
    </inertial>
    <visual>
      <origin
        xyz="0 0 0"
        rpy="0 0 0" />
      <geometry>
        <mesh
          filename="package://simple_hand/meshes/ring_1.STL" />
      </geometry>
      <material
        name="">
        <color
          rgba="0.792156862745098 0.819607843137255 0.933333333333333 1" />
      </material>
    </visual>
    <collision>
      <origin
        xyz="0 0 0"
        rpy="0 0 0" />
      <geometry>
        <mesh
          filename="package://simple_hand/meshes/ring_1.STL" />
      </geometry>
    </collision>
  </link>
  <joint
    name="ring1_rp_palm"
    type="continuous">
    <origin
      xyz="0.011215 0.012454 -0.003"
      rpy="0 0 2.8798" />
    <parent
      link="ring_pink_palm" />
    <child
      link="ring_1" />
    <axis
      xyz="1 0 0" />
  </joint>
  <link
    name="ring_2">
    <inertial>
      <origin
        xyz="0.000100909995286628 0.0146314105773069 0.000100909995284316"
        rpy="0 0 0" />
      <mass
        value="0.0033145763955962" />
      <inertia
        ixx="1.23231389033519E-07"
        ixy="1.90883438607356E-22"
        ixz="3.31705518361765E-22"
        iyy="8.3216699799183E-08"
        iyz="2.37847513333498E-20"
        izz="1.40564829901928E-07" />
    </inertial>
    <visual>
      <origin
        xyz="0 0 0"
        rpy="0 0 0" />
      <geometry>
        <mesh
          filename="package://simple_hand/meshes/ring_2.STL" />
      </geometry>
      <material
        name="">
        <color
          rgba="0.792156862745098 0.819607843137255 0.933333333333333 1" />
      </material>
    </visual>
    <collision>
      <origin
        xyz="0 0 0"
        rpy="0 0 0" />
      <geometry>
        <mesh
          filename="package://simple_hand/meshes/ring_2.STL" />
      </geometry>
    </collision>
  </link>
  <joint
    name="ring_12"
    type="continuous">
    <origin
      xyz="0 -0.01569 0.031714"
      rpy="2.8477 0 3.1416" />
    <parent
      link="ring_1" />
    <child
      link="ring_2" />
    <axis
      xyz="1 0 0" />
  </joint>
  <link
    name="ring_3">
    <inertial>
      <origin
        xyz="0.000294844324682021 0.0161226051015444 -9.48443246825276E-05"
        rpy="0 0 0" />
      <mass
        value="0.00352502395351663" />
      <inertia
        ixx="1.85717997302156E-07"
        ixy="3.76268989676365E-22"
        ixz="6.63431977446779E-23"
        iyy="8.01006878176E-08"
        iyz="-6.78288102293483E-23"
        izz="1.97300854531171E-07" />
    </inertial>
    <visual>
      <origin
        xyz="0 0 0"
        rpy="0 0 0" />
      <geometry>
        <mesh
          filename="package://simple_hand/meshes/ring_3.STL" />
      </geometry>
      <material
        name="">
        <color
          rgba="0.792156862745098 0.819607843137255 0.933333333333333 1" />
      </material>
    </visual>
    <collision>
      <origin
        xyz="0 0 0"
        rpy="0 0 0" />
      <geometry>
        <mesh
          filename="package://simple_hand/meshes/ring_3.STL" />
      </geometry>
    </collision>
  </link>
  <joint
    name="ring_23"
    type="fixed">
    <origin
      xyz="0 0.03 0.0002"
      rpy="0 0 0" />
    <parent
      link="ring_2" />
    <child
      link="ring_3" />
    <axis
      xyz="0 0 0" />
    <limit
      lower="-1.5708"
      upper="0"
      effort="0"
      velocity="0" />
  </joint>
  <link
    name="pinky_1">
    <inertial>
      <origin
        xyz="0.000100909995287481 0.0101314105773068 -0.00289909000470925"
        rpy="0 0 0" />
      <mass
        value="0.00331457639559618" />
      <inertia
        ixx="1.2323138903352E-07"
        ixy="-6.38583432890937E-22"
        ixz="5.11093812141977E-22"
        iyy="8.32166997991832E-08"
        iyz="-2.40485243929882E-20"
        izz="1.40564829901929E-07" />
    </inertial>
    <visual>
      <origin
        xyz="0 0 0"
        rpy="0 0 0" />
      <geometry>
        <mesh
          filename="package://simple_hand/meshes/pinky_1.STL" />
      </geometry>
      <material
        name="">
        <color
          rgba="0.792156862745098 0.819607843137255 0.933333333333333 1" />
      </material>
    </visual>
    <collision>
      <origin
        xyz="0 0 0"
        rpy="0 0 0" />
      <geometry>
        <mesh
          filename="package://simple_hand/meshes/pinky_1.STL" />
      </geometry>
    </collision>
  </link>
  <joint
    name="pinky1_rp_palm"
    type="continuous">
    <origin
      xyz="0.032286 0.01746 -0.003"
      rpy="-3.1416 0 2.7053" />
    <parent
      link="ring_pink_palm" />
    <child
      link="pinky_1" />
    <axis
      xyz="1 0 0" />
  </joint>
  <link
    name="pinky_2">
    <inertial>
      <origin
        xyz="-0.00011619280297661 0.012929255071657 8.38071970190214E-05"
        rpy="0 0 0" />
      <mass
        value="0.00243095694657694" />
      <inertia
        ixx="6.85523277747311E-08"
        ixy="6.07150569613922E-22"
        ixz="5.03477068605157E-22"
        iyy="5.02538415032838E-08"
        iyz="2.40049701524708E-20"
        izz="7.24913923580194E-08" />
    </inertial>
    <visual>
      <origin
        xyz="0 0 0"
        rpy="0 0 0" />
      <geometry>
        <mesh
          filename="package://simple_hand/meshes/pinky_2.STL" />
      </geometry>
      <material
        name="">
        <color
          rgba="0.792156862745098 0.819607843137255 0.933333333333333 1" />
      </material>
    </visual>
    <collision>
      <origin
        xyz="0 0 0"
        rpy="0 0 0" />
      <geometry>
        <mesh
          filename="package://simple_hand/meshes/pinky_2.STL" />
      </geometry>
    </collision>
  </link>
  <joint
    name="pinky_12"
    type="continuous">
    <origin
      xyz="0 0.0255 -0.0028"
      rpy="-3.1416 0 3.1416" />
    <parent
      link="pinky_1" />
    <child
      link="pinky_2" />
    <axis
      xyz="1 0 0" />
  </joint>
  <link
    name="pinky_3">
    <inertial>
      <origin
        xyz="-0.000108084267456392 0.0130882404924839 9.19326081197102E-05"
        rpy="0 0 0" />
      <mass
        value="0.00224742035804122" />
      <inertia
        ixx="7.846384386027E-08"
        ixy="7.56151725249279E-15"
        ixz="-1.75519852389915E-12"
        iyy="4.07217895790232E-08"
        iyz="6.27007155761334E-14"
        izz="7.77279503022194E-08" />
    </inertial>
    <visual>
      <origin
        xyz="0 0 0"
        rpy="0 0 0" />
      <geometry>
        <mesh
          filename="package://simple_hand/meshes/pinky_3.STL" />
      </geometry>
      <material
        name="">
        <color
          rgba="0.792156862745098 0.819607843137255 0.933333333333333 1" />
      </material>
    </visual>
    <collision>
      <origin
        xyz="0 0 0"
        rpy="0 0 0" />
      <geometry>
        <mesh
          filename="package://simple_hand/meshes/pinky_3.STL" />
      </geometry>
    </collision>
  </link>
  <joint
    name="pinky_23"
    type="fixed">
    <origin
      xyz="0 0.02675 0"
      rpy="0 0 0" />
    <parent
      link="pinky_2" />
    <child
      link="pinky_3" />
    <axis
      xyz="1 0 0" />
    <limit
      lower="-1.5708"
      upper="0"
      effort="0"
      velocity="0" />
  </joint>
</robot>