<?xml version="1.0" encoding="utf-8"?>
<!-- This URDF was automatically created by SolidWorks to URDF Exporter! Originally created by Stephen Brawner (brawner@gmail.com) 
     Commit Version: 1.6.0-1-g15f4949  Build Version: 1.6.7594.29634
     For more information, please see http://wiki.ros.org/sw_urdf_exporter -->
<robot
  name="simple_hand_2">
  <link
    name="base_link">
    <inertial>
      <origin
        xyz="-0.00188643436581484 7.91792044075344E-07 -0.0101107102609225"
        rpy="0 0 0" />
      <mass
        value="0.0547254839327602" />
      <inertia
        ixx="3.01578866609305E-05"
        ixy="2.75922512249631E-11"
        ixz="5.77313895814659E-06"
        iyy="4.6585768516949E-05"
        iyz="-3.08656421612755E-11"
        izz="1.82716186853849E-05" />
    </inertial>
    <visual>
      <origin
        xyz="0 0 0"
        rpy="0 0 0" />
      <geometry>
        <mesh
          filename="package://simple_hand_2/meshes/base_link.STL" />
      </geometry>
      <material
        name="">
        <color
          rgba="0.792156862745098 0.819607843137255 0.933333333333333 1" />
      </material>
    </visual>
    <collision>
      <origin
        xyz="0 0 0"
        rpy="0 0 0" />
      <geometry>
        <mesh
          filename="package://simple_hand_2/meshes/base_link.STL" />
      </geometry>
    </collision>
  </link>
  <link
    name="thumb_1">
    <inertial>
      <origin
        xyz="0.0048085282615066 0.0155683292090754 -9.38862231650911E-05"
        rpy="0 0 0" />
      <mass
        value="0.00714658380829061" />
      <inertia
        ixx="3.26626039983406E-07"
        ixy="9.21851511766135E-08"
        ixz="7.28401970577256E-11"
        iyy="4.93450737768554E-07"
        iyz="1.16674127798381E-10"
        izz="6.67805464749945E-07" />
    </inertial>
    <visual>
      <origin
        xyz="0 0 0"
        rpy="0 0 0" />
      <geometry>
        <mesh
          filename="package://simple_hand_2/meshes/thumb_1.STL" />
      </geometry>
      <material
        name="">
        <color
          rgba="0.792156862745098 0.819607843137255 0.933333333333333 1" />
      </material>
    </visual>
    <collision>
      <origin
        xyz="0 0 0"
        rpy="0 0 0" />
      <geometry>
        <mesh
          filename="package://simple_hand_2/meshes/thumb_1.STL" />
      </geometry>
    </collision>
  </link>
  <joint
    name="thumb_palm"
    type="continuous">
    <origin
      xyz="-0.031 -0.0001 0"
      rpy="1.3963 1.5708 0" />
    <parent
      link="base_link" />
    <child
      link="thumb_1" />
    <axis
      xyz="1 0 0" />
  </joint>
  <link
    name="thumb_2">
    <inertial>
      <origin
        xyz="-0.0580525842144154 0.0245170365772043 0.00600212157284601"
        rpy="0 0 0" />
      <mass
        value="0.00309410697808253" />
      <inertia
        ixx="9.86716393307872E-08"
        ixy="-6.58381417150374E-09"
        ixz="4.76941858010113E-11"
        iyy="8.17761446626134E-08"
        iyz="1.44734613015972E-11"
        izz="1.17680540570393E-07" />
    </inertial>
    <visual>
      <origin
        xyz="0 0 0"
        rpy="0 0 0" />
      <geometry>
        <mesh
          filename="package://simple_hand_2/meshes/thumb_2.STL" />
      </geometry>
      <material
        name="">
        <color
          rgba="0.792156862745098 0.819607843137255 0.933333333333333 1" />
      </material>
    </visual>
    <collision>
      <origin
        xyz="0 0 0"
        rpy="0 0 0" />
      <geometry>
        <mesh
          filename="package://simple_hand_2/meshes/thumb_2.STL" />
      </geometry>
    </collision>
  </link>
  <joint
    name="thumb_12"
    type="continuous">
    <origin
      xyz="0.00074168 -0.025588 -0.0138"
      rpy="-2.8356 0.43178 -1.5075" />
    <parent
      link="thumb_1" />
    <child
      link="thumb_2" />
    <axis
      xyz="1 0 0" />
  </joint>
  <link
    name="thumb_3">
    <inertial>
      <origin
        xyz="-0.0683569874934218 0.0647531465127786 0.00599440013402116"
        rpy="0 0 0" />
      <mass
        value="0.00324861748801509" />
      <inertia
        ixx="1.31829885963988E-07"
        ixy="2.37227938008642E-08"
        ixz="1.16060719332412E-12"
        iyy="8.56030195353302E-08"
        iyz="9.31995554639708E-13"
        izz="1.54481533062546E-07" />
    </inertial>
    <visual>
      <origin
        xyz="0 0 0"
        rpy="0 0 0" />
      <geometry>
        <mesh
          filename="package://simple_hand_2/meshes/thumb_3.STL" />
      </geometry>
      <material
        name="">
        <color
          rgba="0.792156862745098 0.819607843137255 0.933333333333333 1" />
      </material>
    </visual>
    <collision>
      <origin
        xyz="0 0 0"
        rpy="0 0 0" />
      <geometry>
        <mesh
          filename="package://simple_hand_2/meshes/thumb_3.STL" />
      </geometry>
    </collision>
  </link>
  <joint
    name="thumb_23"
    type="continuous">
    <origin
      xyz="0.010488 -0.0027249 0.0098784"
      rpy="0.031976 -0.17161 0.12773" />
    <parent
      link="thumb_2" />
    <child
      link="thumb_3" />
    <axis
      xyz="1 0 0" />
  </joint>
  <link
    name="index_1">
    <inertial>
      <origin
        xyz="0.000100909995287481 0.0101314105773068 -0.00308812397054953"
        rpy="0 0 0" />
      <mass
        value="0.00331457639559618" />
      <inertia
        ixx="1.2323138903352E-07"
        ixy="-6.25963302176875E-22"
        ixz="5.10019588239712E-22"
        iyy="8.32166997991831E-08"
        iyz="-2.40399965955461E-20"
        izz="1.40564829901929E-07" />
    </inertial>
    <visual>
      <origin
        xyz="0 0 0"
        rpy="0 0 0" />
      <geometry>
        <mesh
          filename="package://simple_hand_2/meshes/index_1.STL" />
      </geometry>
      <material
        name="">
        <color
          rgba="0.792156862745098 0.819607843137255 0.933333333333333 1" />
      </material>
    </visual>
    <collision>
      <origin
        xyz="0 0 0"
        rpy="0 0 0" />
      <geometry>
        <mesh
          filename="package://simple_hand_2/meshes/index_1.STL" />
      </geometry>
    </collision>
  </link>
  <joint
    name="index_palm"
    type="continuous">
    <origin
      xyz="-0.0299 0.0029 0.043"
      rpy="1.5708 0 3.1416" />
    <parent
      link="base_link" />
    <child
      link="index_1" />
    <axis
      xyz="-1 0 0" />
  </joint>
  <link
    name="index_2">
    <inertial>
      <origin
        xyz="8.81239705526511E-05 0.0101314105773068 -0.00291187602944456"
        rpy="0 0 0" />
      <mass
        value="0.00331457639559618" />
      <inertia
        ixx="1.2323138903352E-07"
        ixy="-6.31603140027893E-22"
        ixz="5.08654045052711E-22"
        iyy="8.32166997991831E-08"
        iyz="-2.3986539712562E-20"
        izz="1.40564829901929E-07" />
    </inertial>
    <visual>
      <origin
        xyz="0 0 0"
        rpy="0 0 0" />
      <geometry>
        <mesh
          filename="package://simple_hand_2/meshes/index_2.STL" />
      </geometry>
      <material
        name="">
        <color
          rgba="0.792156862745098 0.819607843137255 0.933333333333333 1" />
      </material>
    </visual>
    <collision>
      <origin
        xyz="0 0 0"
        rpy="0 0 0" />
      <geometry>
        <mesh
          filename="package://simple_hand_2/meshes/index_2.STL" />
      </geometry>
    </collision>
  </link>
  <joint
    name="index_12"
    type="continuous">
    <origin
      xyz="0.0002 0.03 0"
      rpy="0 0 0" />
    <parent
      link="index_1" />
    <child
      link="index_2" />
    <axis
      xyz="1 0 0" />
  </joint>
  <link
    name="index_3">
    <inertial>
      <origin
        xyz="-9.48443246826212E-05 0.0116226051015443 -0.00309484432468262"
        rpy="0 0 0" />
      <mass
        value="0.00352502395351663" />
      <inertia
        ixx="1.85717997302154E-07"
        ixy="-1.99224311388662E-23"
        ixz="-3.7181621830391E-24"
        iyy="8.01006878176001E-08"
        iyz="-4.00691042258123E-23"
        izz="1.97300854531169E-07" />
    </inertial>
    <visual>
      <origin
        xyz="0 0 0"
        rpy="0 0 0" />
      <geometry>
        <mesh
          filename="package://simple_hand_2/meshes/index_3.STL" />
      </geometry>
      <material
        name="">
        <color
          rgba="0.792156862745098 0.819607843137255 0.933333333333333 1" />
      </material>
    </visual>
    <collision>
      <origin
        xyz="0 0 0"
        rpy="0 0 0" />
      <geometry>
        <mesh
          filename="package://simple_hand_2/meshes/index_3.STL" />
      </geometry>
    </collision>
  </link>
  <joint
    name="index_23"
    type="fixed">
    <origin
      xyz="0 0.03 0"
      rpy="0 0 0" />
    <parent
      link="index_2" />
    <child
      link="index_3" />
    <axis
      xyz="0 0 0" />
  </joint>
  <link
    name="middle_1">
    <inertial>
      <origin
        xyz="-0.0075009099952875 8.81239705495927E-05 -0.0146314105773068"
        rpy="0 0 0" />
      <mass
        value="0.00331457639559618" />
      <inertia
        ixx="1.2323138903352E-07"
        ixy="5.10801247889187E-22"
        ixz="-6.3746455157721E-22"
        iyy="1.40564829901929E-07"
        iyz="-2.41810386122092E-20"
        izz="8.32166997991832E-08" />
    </inertial>
    <visual>
      <origin
        xyz="0 0 0"
        rpy="0 0 0" />
      <geometry>
        <mesh
          filename="package://simple_hand_2/meshes/middle_1.STL" />
      </geometry>
      <material
        name="">
        <color
          rgba="0.792156862745098 0.819607843137255 0.933333333333333 1" />
      </material>
    </visual>
    <collision>
      <origin
        xyz="0 0 0"
        rpy="0 0 0" />
      <geometry>
        <mesh
          filename="package://simple_hand_2/meshes/middle_1.STL" />
      </geometry>
    </collision>
  </link>
  <joint
    name="middle_palm"
    type="continuous">
    <origin
      xyz="-0.003 0.000100000000000004 0.0435"
      rpy="-3.14159265358979 0 0" />
    <parent
      link="base_link" />
    <child
      link="middle_1" />
    <axis
      xyz="1 0 0" />
  </joint>
  <link
    name="middle_2">
    <inertial>
      <origin
        xyz="0.000100909995287477 -0.0491314105773069 -0.0330881239705554"
        rpy="0 0 0" />
      <mass
        value="0.00331457639559618" />
      <inertia
        ixx="1.2323138903352E-07"
        ixy="6.09867234555869E-22"
        ixz="-5.09255366438186E-22"
        iyy="8.32166997991831E-08"
        iyz="-2.4011489069115E-20"
        izz="1.40564829901928E-07" />
    </inertial>
    <visual>
      <origin
        xyz="0 0 0"
        rpy="0 0 0" />
      <geometry>
        <mesh
          filename="package://simple_hand_2/meshes/middle_2.STL" />
      </geometry>
      <material
        name="">
        <color
          rgba="0.792156862745098 0.819607843137255 0.933333333333333 1" />
      </material>
    </visual>
    <collision>
      <origin
        xyz="0 0 0"
        rpy="0 0 0" />
      <geometry>
        <mesh
          filename="package://simple_hand_2/meshes/middle_2.STL" />
      </geometry>
    </collision>
  </link>
  <joint
    name="middle_12"
    type="continuous">
    <origin
      xyz="-0.0076 0.033 0.0045"
      rpy="1.5708 0 3.1416" />
    <parent
      link="middle_1" />
    <child
      link="middle_2" />
    <axis
      xyz="1 0 0" />
  </joint>
  <link
    name="middle_3">
    <inertial>
      <origin
        xyz="-9.48443246825987E-05 -0.110622605101544 -0.0330948443246824"
        rpy="0 0 0" />
      <mass
        value="0.00352502395351662" />
      <inertia
        ixx="1.85717997302153E-07"
        ixy="5.55896476099517E-23"
        ixz="1.76231881583275E-23"
        iyy="8.01006878176E-08"
        iyz="5.01247558570527E-23"
        izz="1.97300854531168E-07" />
    </inertial>
    <visual>
      <origin
        xyz="0 0 0"
        rpy="0 0 0" />
      <geometry>
        <mesh
          filename="package://simple_hand_2/meshes/middle_3.STL" />
      </geometry>
      <material
        name="">
        <color
          rgba="0.792156862745098 0.819607843137255 0.933333333333333 1" />
      </material>
    </visual>
    <collision>
      <origin
        xyz="0 0 0"
        rpy="0 0 0" />
      <geometry>
        <mesh
          filename="package://simple_hand_2/meshes/middle_3.STL" />
      </geometry>
    </collision>
  </link>
  <joint
    name="middle_23"
    type="fixed">
    <origin
      xyz="0.0002 0.03 0"
      rpy="0 0 0" />
    <parent
      link="middle_2" />
    <child
      link="middle_3" />
    <axis
      xyz="0 0 0" />
  </joint>
  <link
    name="ring_pink_palm">
    <inertial>
      <origin
        xyz="0.0170207672540449 0.00634175647982317 -8.33728651589362E-05"
        rpy="0 0 0" />
      <mass
        value="0.00474638182867952" />
      <inertia
        ixx="1.24617700851684E-07"
        ixy="8.08014945109771E-08"
        ixz="-3.25122701376156E-12"
        iyy="4.61877650491779E-07"
        iyz="1.81183357334928E-12"
        izz="4.81107731413793E-07" />
    </inertial>
    <visual>
      <origin
        xyz="0 0 0"
        rpy="0 0 0" />
      <geometry>
        <mesh
          filename="package://simple_hand_2/meshes/ring_pink_palm.STL" />
      </geometry>
      <material
        name="">
        <color
          rgba="0.792156862745098 0.819607843137255 0.933333333333333 1" />
      </material>
    </visual>
    <collision>
      <origin
        xyz="0 0 0"
        rpy="0 0 0" />
      <geometry>
        <mesh
          filename="package://simple_hand_2/meshes/ring_pink_palm.STL" />
      </geometry>
    </collision>
  </link>
  <joint
    name="rp_palm"
    type="continuous">
    <origin
      xyz="0.0032512 0.0001 0.018439"
      rpy="1.5708 0 0" />
    <parent
      link="base_link" />
    <child
      link="ring_pink_palm" />
    <axis
      xyz="0.98481 -0.17365 0" />
  </joint>
  <link
    name="ring_1">
    <inertial>
      <origin
        xyz="8.73292782364032E-05 -0.0209311545992939 0.00308732927822884"
        rpy="0 0 0" />
      <mass
        value="0.00334473888459068" />
      <inertia
        ixx="1.23940526073648E-07"
        ixy="1.16797902492488E-21"
        ixz="-1.0531057297454E-21"
        iyy="8.36234289464328E-08"
        iyz="-4.91864785874036E-20"
        izz="1.41586346370184E-07" />
    </inertial>
    <visual>
      <origin
        xyz="0 0 0"
        rpy="0 0 0" />
      <geometry>
        <mesh
          filename="package://simple_hand_2/meshes/ring_1.STL" />
      </geometry>
      <material
        name="">
        <color
          rgba="0.792156862745098 0.819607843137255 0.933333333333333 1" />
      </material>
    </visual>
    <collision>
      <origin
        xyz="0 0 0"
        rpy="0 0 0" />
      <geometry>
        <mesh
          filename="package://simple_hand_2/meshes/ring_1.STL" />
      </geometry>
    </collision>
  </link>
  <joint
    name="ring1_rp_palm"
    type="continuous">
    <origin
      xyz="0.011215 0.012454 -0.003"
      rpy="0 0 2.8798" />
    <parent
      link="ring_pink_palm" />
    <child
      link="ring_1" />
    <axis
      xyz="1 0 0" />
  </joint>
  <link
    name="ring_2">
    <inertial>
      <origin
        xyz="0.00010090999528985 -0.0426886524241691 0.0169749492455598"
        rpy="0 0 0" />
      <mass
        value="0.00331457639559613" />
      <inertia
        ixx="1.2323138903352E-07"
        ixy="-4.75356350150911E-22"
        ixz="-7.08881276752877E-22"
        iyy="8.8028771725466E-08"
        iyz="-1.58999148006687E-08"
        izz="1.35752757975645E-07" />
    </inertial>
    <visual>
      <origin
        xyz="0 0 0"
        rpy="0 0 0" />
      <geometry>
        <mesh
          filename="package://simple_hand_2/meshes/ring_2.STL" />
      </geometry>
      <material
        name="">
        <color
          rgba="0.792156862745098 0.819607843137255 0.933333333333333 1" />
      </material>
    </visual>
    <collision>
      <origin
        xyz="0 0 0"
        rpy="0 0 0" />
      <geometry>
        <mesh
          filename="package://simple_hand_2/meshes/ring_2.STL" />
      </geometry>
    </collision>
  </link>
  <joint
    name="ring_12"
    type="continuous">
    <origin
      xyz="0 -0.01569 0.031714"
      rpy="2.8477 0 3.1416" />
    <parent
      link="ring_1" />
    <child
      link="ring_2" />
    <axis
      xyz="1 0 0" />
  </joint>
  <link
    name="ring_3">
    <inertial>
      <origin
        xyz="0.00029484432468546 -0.102828463435009 0.00764877026309346"
        rpy="0 0 0" />
      <mass
        value="0.00352502395351663" />
      <inertia
        ixx="1.85717997302152E-07"
        ixy="-7.91980234167709E-23"
        ixz="-4.33876445657651E-23"
        iyy="8.99349340430514E-08"
        iyz="-3.24940440435221E-08"
        izz="1.87466608305716E-07" />
    </inertial>
    <visual>
      <origin
        xyz="0 0 0"
        rpy="0 0 0" />
      <geometry>
        <mesh
          filename="package://simple_hand_2/meshes/ring_3.STL" />
      </geometry>
      <material
        name="">
        <color
          rgba="0.792156862745098 0.819607843137255 0.933333333333333 1" />
      </material>
    </visual>
    <collision>
      <origin
        xyz="0 0 0"
        rpy="0 0 0" />
      <geometry>
        <mesh
          filename="package://simple_hand_2/meshes/ring_3.STL" />
      </geometry>
    </collision>
  </link>
  <joint
    name="ring_23"
    type="fixed">
    <origin
      xyz="0 0.03 0.0002"
      rpy="0 0 0" />
    <parent
      link="ring_2" />
    <child
      link="ring_3" />
    <axis
      xyz="0 0 0" />
    <limit
      lower="-1.5708"
      upper="0"
      effort="0"
      velocity="0" />
  </joint>
  <link
    name="pinky_1">
    <inertial>
      <origin
        xyz="0.000100909995289757 0.0101314105773062 -0.00289909000470925"
        rpy="0 0 0" />
      <mass
        value="0.00331457639559618" />
      <inertia
        ixx="1.2323138903352E-07"
        ixy="-6.25348543090089E-22"
        ixz="5.09918288209813E-22"
        iyy="8.32166997991832E-08"
        iyz="-2.40511916377306E-20"
        izz="1.40564829901929E-07" />
    </inertial>
    <visual>
      <origin
        xyz="0 0 0"
        rpy="0 0 0" />
      <geometry>
        <mesh
          filename="package://simple_hand_2/meshes/pinky_1.STL" />
      </geometry>
      <material
        name="">
        <color
          rgba="0.792156862745098 0.819607843137255 0.933333333333333 1" />
      </material>
    </visual>
    <collision>
      <origin
        xyz="0 0 0"
        rpy="0 0 0" />
      <geometry>
        <mesh
          filename="package://simple_hand_2/meshes/pinky_1.STL" />
      </geometry>
    </collision>
  </link>
  <joint
    name="pinky1_rp_palm"
    type="continuous">
    <origin
      xyz="0.032286 0.01746 -0.003"
      rpy="-3.1416 0 2.7053" />
    <parent
      link="ring_pink_palm" />
    <child
      link="pinky_1" />
    <axis
      xyz="1 0 0" />
  </joint>
  <link
    name="pinky_2">
    <inertial>
      <origin
        xyz="-0.000116192802976579 0.0129292550716577 8.38071970190243E-05"
        rpy="0 0 0" />
      <mass
        value="0.00243095694657695" />
      <inertia
        ixx="6.85523277747313E-08"
        ixy="6.99794798219861E-22"
        ixz="5.30375999095151E-22"
        iyy="5.02538415032839E-08"
        iyz="2.4009285103902E-20"
        izz="7.24913923580197E-08" />
    </inertial>
    <visual>
      <origin
        xyz="0 0 0"
        rpy="0 0 0" />
      <geometry>
        <mesh
          filename="package://simple_hand_2/meshes/pinky_2.STL" />
      </geometry>
      <material
        name="">
        <color
          rgba="0.792156862745098 0.819607843137255 0.933333333333333 1" />
      </material>
    </visual>
    <collision>
      <origin
        xyz="0 0 0"
        rpy="0 0 0" />
      <geometry>
        <mesh
          filename="package://simple_hand_2/meshes/pinky_2.STL" />
      </geometry>
    </collision>
  </link>
  <joint
    name="pinky_12"
    type="continuous">
    <origin
      xyz="0 0.0255 -0.0028"
      rpy="-3.1416 0 3.1416" />
    <parent
      link="pinky_1" />
    <child
      link="pinky_2" />
    <axis
      xyz="1 0 0" />
  </joint>
  <link
    name="pinky_3">
    <inertial>
      <origin
        xyz="-0.000108084267458654 0.0130882404924846 9.19326081197115E-05"
        rpy="0 0 0" />
      <mass
        value="0.00224742035804122" />
      <inertia
        ixx="7.84638438602707E-08"
        ixy="7.56151801184459E-15"
        ixz="-1.75519852388493E-12"
        iyy="4.07217895790235E-08"
        iyz="6.27007155808155E-14"
        izz="7.77279503022204E-08" />
    </inertial>
    <visual>
      <origin
        xyz="0 0 0"
        rpy="0 0 0" />
      <geometry>
        <mesh
          filename="package://simple_hand_2/meshes/pinky_3.STL" />
      </geometry>
      <material
        name="">
        <color
          rgba="0.792156862745098 0.819607843137255 0.933333333333333 1" />
      </material>
    </visual>
    <collision>
      <origin
        xyz="0 0 0"
        rpy="0 0 0" />
      <geometry>
        <mesh
          filename="package://simple_hand_2/meshes/pinky_3.STL" />
      </geometry>
    </collision>
  </link>
  <joint
    name="pinky_23"
    type="fixed">
    <origin
      xyz="0 0.02675 0"
      rpy="0 0 0" />
    <parent
      link="pinky_2" />
    <child
      link="pinky_3" />
    <axis
      xyz="0 0 0" />
    <limit
      lower="-1.5708"
      upper="0"
      effort="0"
      velocity="0" />
  </joint>
</robot>